Workbook

Sheet DASHBOARD

Sheet Sheet10
A3: Row Labels | B3: Sum of Total mothers per year
A4: 2008 | B4: 64341
A5: 2007 | B5: 64041 | F5: Row Labels | G5: Sum of Total Valid Birth Count
A6: 2010 | B6: 63894 | F6: 2007 | G6: 1082331
A7: 2009 | B7: 62541 | F7: 2008 | G7: 1082331
A8: 2011 | B8: 61404 | F8: 2009 | G8: 1082331
A9: Grand Total | B9: 316221 | F9: 2010 | G9: 1082331
F10: 2011 | G10: 1082331
F11: 2005 | G11: 1082331
F12: 2006 | G12: 1082331 | M12: Sum of Total mothers per year
F13: 2012 | G13: 1082331 | M13: 1083168
F14: 2013 | G14: 1082331
F15: 2014 | G15: 1082331
F16: 2015 | G16: 1082331
F17: 2016 | G17: 1082331
F18: 2017 | G18: 1082331
F19: 2018 | G19: 1082331
F20: 2019 | G20: 1082331
F21: 2020 | G21: 1082331
F22: 2021 | G22: 1082331
F23: 2022 | G23: 1082331
F24: Grand Total | G24: 1082331

Sheet Sheet8
A3: Row Labels | B3: Average of Total_number of Mothers <20 years
A4: 2008 | B4: 5223 | D4: Row Labels | E4: Sum of Total_number of Mothers <20 years
A5: 2007 | B5: 4953 | D5: 57219 | E5: 2922
A6: 2009 | B6: 4671 | D6: 57546 | E6: 1893 | I6: Row Labels | J6: Average of Total_number of Mothers >40 years
A7: 2010 | B7: 4551 | D7: 57675 | E7: 4134 | I7: 2012 | J7: 2634
A8: 2006 | B8: 4374 | D8: 57996 | E8: 2076 | I8: 2010 | J8: 2622
A9: Grand Total | B9: 4754.4 | D9: 58647 | E9: 1596 | I9: 2013 | J9: 2583
D10: 58701 | E10: 3303 | I10: 2011 | J10: 2544
D11: 58881 | E11: 1719 | I11: 2015 | J11: 2541
D12: 59058 | E12: 4374 | I12: Grand Total | J12: 2584.8
D13: 59406 | E13: 2481
D14: 59595 | E14: 2316
D15: 59613 | E15: 1995
D16: 61029 | E16: 2865
D17: 61164 | E17: 3786 | J17: Row Labels | K17: Sum of Total Valid Birth Count
D18: 61380 | E18: 4008 | J18: 2008 | K18: 64278
D19: 62457 | E19: 4671 | J19: 2007 | K19: 63873
D20: 63813 | E20: 4551 | J20: 2010 | K20: 63813
D21: 63873 | E21: 4953 | J21: 2009 | K21: 62457
D22: 64278 | E22: 5223 | J22: 2011 | K22: 61380
D23: Grand Total | E23: 58866 | J23: Grand Total | K23: 315801

Sheet Report
A1: Period | B1: Total Valid Birth Count | C1: Total mothers per year | D1: Mothers with 2+ births per year | E1: Column1 | F1: % of mothers < 20 years | G1: % of mother < 20 / 100 | H1: Total_number of Mothers <20 years | I1: % of mothers between 20 & 39 years | J1: % of mothers (20-39)/100 | K1: Total_number of Mothers 20-39 years | L1: % of mothers > 40 years | M1: % of mother > 40 / 100 | N1: Total_number of Mothers >40 years | O1: Column2 | P1: % of mothers =/> 20 | Q1: Column3 | R1: Aging Maternal Metrics | S1: Column4 | T1: Column5 | U1: Teen Pregnancy Metrics | V1: Column6 | W1: Column7 | X1: Y-o-Y change | Y1: Column8 | Z1: Column9 | AA1: Column10
A2: 2005 | B2: 57675 | C2: 57738 | D2: 63 | F2: 7.1599293 | G2: 0.071599293 | H2: 4134 | I2: 89.213343 | J2: 0.89213343 | K2: 51510 | L2: 3.6267276 | M2: 0.036267276 | N2: 2094 | P2: 92.840071 | R2: Mothers > 40 2005 (%) | S2: 3.6267276 | U2: Teen Mother in 2005 (%) | V2: 7.1599293 | X2: YoY change - Mothers > 40 | Y2: 0.022352496 | Z2: YoY change - Teen Mothers | AA2: 0.22945792
A3: 2006 | B3: 59058 | C3: 59193 | D3: 135 | F3: 7.3893873 | G3: 0.073893873 | H3: 4374 | I3: 88.961533 | J3: 0.88961533 | K3: 52659 | L3: 3.6490801 | M3: 0.036490801 | N3: 2160 | P3: 92.610613 | R3: Mothers > 40 2022 (%) | S3: 4.0399409 | U3: Teen Mother in 2022 (%) | V3: 2.9191502 | Y3: 0.065727574 | AA3: 0.34472058
A4: 2007 | B4: 63873 | C4: 64041 | D4: 168 | F4: 7.7341078 | G4: 0.077341078 | H4: 4953 | I4: 88.551084 | J4: 0.88551084 | K4: 56709 | L4: 3.7148077 | M4: 0.037148077 | N4: 2379 | P4: 92.265892 | R4: Absolute Change (% point) | S4: 0.41321327 | U4: Absolute Decline (% point) | V4: 4.2407791 | Y4: -0.012658217 | AA4: 0.38357762
A5: 2008 | B5: 64278 | C5: 64341 | D5: 63 | F5: 8.1176855 | G5: 0.081176855 | H5: 5223 | I5: 88.180165 | J5: 0.88180165 | K5: 56736 | L5: 3.7021495 | M5: 0.037021495 | N5: 2382 | P5: 91.882315 | R5: Relative change (%) | S5: 11.393557 | U5: Relative Decline(%) | V5: 59.229343 | Y5: 0.22647334 | AA5: -0.64898492
A6: 2009 | B6: 62457 | C6: 62541 | D6: 84 | F6: 7.4687005 | G6: 0.074687005 | H6: 4671 | I6: 88.602677 | J6: 0.88602677 | K6: 55413 | L6: 3.9286228 | M6: 0.039286228 | N6: 2457 | P6: 92.531299 | R6: Average annual change(% point) | S6: 0.024306663 | U6: Average Annual Decline (% point) | V6: 0.24945759 | Y6: 0.17504888 | AA6: -0.345966
A7: 2010 | B7: 63813 | C7: 63894 | D7: 81 | F7: 7.1227345 | G7: 0.071227345 | H7: 4551 | I7: 88.773594 | J7: 0.88773594 | K7: 56721 | L7: 4.1036717 | M7: 0.041036717 | N7: 2622 | P7: 92.877265 | R7: Actual Birth to Mother > 40 in 2005 | S7: 2091.7152 | U7: Actual Teen Birth in 2005 | V7: 4129.4892 | Y7: 0.039380864 | AA7: -0.59547246
A8: 2011 | B8: 61380 | C8: 61404 | D8: 24 | F8: 6.5272621 | G8: 0.065272621 | H8: 4008 | I8: 89.329685 | J8: 0.89329685 | K8: 54852 | L8: 4.1430526 | M8: 0.041430526 | N8: 2544 | P8: 93.472738 | R8: Actual Birth to Mother > 40 in 2022 | S8: 2378.7576 | U8: Actual Teen Birth in 2005 | V8: 1718.8249 | Y8: 0.16234634 | AA8: -0.33886409
A9: 2012 | B9: 61164 | C9: 61179 | D9: 15 | F9: 6.188398 | G9: 0.06188398 | H9: 3786 | I9: 89.506203 | J9: 0.89506203 | K9: 54759 | L9: 4.3053989 | M9: 0.043053989 | N9: 2634 | P9: 93.811602 | U9: Reduction in Teen Birth | V9: 2410.6644 | Y9: 0.093068522 | AA9: -0.56387691
A10: 2013 | B10: 58701 | C10: 58725 | D10: 24 | F10: 5.6245211 | G10: 0.056245211 | H10: 3303 | I10: 89.977011 | J10: 0.89977011 | K10: 52839 | L10: 4.3984674 | M10: 0.043984674 | N10: 2583 | P10: 94.375479 | R10: Year with largest increase in mothers > 40 | S10: 2013 | U10: % Reduction actual Teen Birth | V10: 58.376817 | Y10: -0.10077351 | AA10: -0.51969927
A11: 2014 | B11: 57219 | C11: 57240 | D11: 21 | F11: 5.1048218 | G11: 0.051048218 | H11: 2922 | I11: 90.597484 | J11: 0.90597484 | K11: 51858 | L11: 4.2976939 | M11: 0.042976939 | N11: 2460 | P11: 94.895178 | R11: Year with lowest number of mothers > 40 | S11: 2005 | Y11: -0.13491808 | AA11: -0.41125518
A12: 2015 | B12: 61029 | C12: 61041 | D12: 12 | F12: 4.6935666 | G12: 0.046935666 | H12: 2865 | I12: 91.143658 | J12: 0.91143658 | K12: 55635 | L12: 4.1627758 | M12: 0.041627758 | N12: 2541 | P12: 95.306433 | U12: Year with the largest decrease in teen mothers | V12: 2021 | Y12: -0.10926751 | AA12: -0.51890736
A13: 2016 | B13: 59406 | C13: 59430 | D13: 24 | F13: 4.1746593 | G13: 0.041746593 | H13: 2481 | I13: 91.771832 | J13: 0.91771832 | K13: 54540 | L13: 4.0535083 | M13: 0.040535083 | N13: 2409 | P13: 95.825341 | U13: Year with the highest number of teen mothers | V13: 2008 | Y13: 0.043119753 | AA13: -0.28940511
A14: 2017 | B14: 59595 | C14: 59610 | D14: 15 | F14: 3.8852542 | G14: 0.038852542 | H14: 2316 | I14: 92.018118 | J14: 0.92018118 | K14: 54852 | L14: 4.0966281 | M14: 0.040966281 | N14: 2442 | P14: 96.114746 | Y14: -0.13592488 | AA14: -0.30717763
A15: 2018 | B15: 57996 | C15: 58020 | D15: 24 | F15: 3.5780765 | G15: 0.035780765 | H15: 2076 | I15: 92.46122 | J15: 0.9246122 | K15: 53646 | L15: 3.9607032 | M15: 0.039607032 | N15: 2298 | P15: 96.421923 | Y15: 0.098448748 | AA15: -0.23317436
A16: 2019 | B16: 59613 | C16: 59643 | D16: 30 | F16: 3.3449022 | G16: 0.033449022 | H16: 1995 | I16: 92.595946 | J16: 0.92595946 | K16: 55227 | L16: 4.059152 | M16: 0.04059152 | N16: 2421 | P16: 96.655098 | Y16: -0.15107004 | AA16: -0.056902585
A17: 2020 | B17: 57546 | C17: 57573 | D17: 27 | F17: 3.2879996 | G17: 0.032879996 | H17: 1893 | I17: 92.803919 | J17: 0.92803919 | K17: 53430 | L17: 3.9080819 | M17: 0.039080819 | N17: 2250 | P17: 96.712 | Y17: -0.098509404 | AA17: -0.56760686
A18: 2021 | B18: 58647 | C18: 58668 | D18: 21 | F18: 2.7203927 | G18: 0.027203927 | H18: 1596 | I18: 93.470035 | J18: 0.93470035 | K18: 54837 | L18: 3.8095725 | M18: 0.038095725 | N18: 2235 | P18: 97.279607 | Y18: 0.23036839 | AA18: 0.19875752
A19: 2022 | B19: 58881 | C19: 58887 | D19: 6 | F19: 2.9191502 | G19: 0.029191502 | H19: 1719 | I19: 93.040909 | J19: 0.93040909 | K19: 54789 | L19: 4.0399409 | M19: 0.040399409 | N19: 2379 | P19: 97.08085 | Y19: -4.0399409 | AA19: -2.9191502

Sheet Analysis
A1: {=TRIM('births-deaths-natural-increase'!A1:A24)} -> Period | B1: Total Valid Birth Count | C1: Total mothers per year | D1: Mothers with 2+ births per year | F1: % of mothers < 20 years | G1: % of mother < 20 / 100 | H1: Total_number of Mothers <20 years | I1: % of mothers between 20 & 39 years | J1: % of mothers (20-39)/100 | K1: Total_number of Mothers 20-39 years | L1: % of mothers > 40 years | M1: % of mother > 40 / 100 | N1: Total_number of Mothers >40 years | P1: % of mothers =/> 20 | R1: Medain Age of mother | T1: Aging Maternal Metrics | W1: Teen Pregnancy Metrics | Z1: Y-o-Y change
A2: 2000 | B2: N/A
A3: 2001 | B3: N/A
A4: 2002 | B4: N/A
A5: 2003 | B5: N/A
A6: 2004 | B6: N/A
A7: 2005 | B7: =SUM('births-deaths-by-region'!$D$2:$D$17) -> 57675 | C7: =SUM('births-by-mothers-age'!$C$2:$C$9) -> 57738 | D7: =C7-B7 -> 63 | F7: =SUM('births-by-mothers-age'!$C$2:$C$3)/$C$7 * 100 -> 7.1599293 | G7: =F7/100 -> 0.071599293 | H7: =G7 * C7 -> 4134 | I7: =SUM('births-by-mothers-age'!$C$4:$C$7)/$C$7 *100 -> 89.213343 | J7: =I7/100 -> 0.89213343 | K7: =C7*J7 -> 51510 | L7: =SUM('births-by-mothers-age'!$C$8:$C$9)/$C$7 *100 -> 3.6267276 | M7: =L7/100 -> 0.036267276 | N7: =C7*M7 -> 2094 | P7: =I7+L7 -> 92.840071 | T7: Mothers > 40 2005 (%) | U7: =L7 -> 3.6267276 | W7: Teen Mother in 2005 (%) | X7: =F7 -> 7.1599293 | Z7: YoY change - Mothers > 40 | AA7: =L8-L7 -> 0.022352496 | AB7: YoY change - Teen Mothers | AC7: =F8-F7 -> 0.22945792
A8: 2006 | B8: =SUM('births-deaths-by-region'!$D$38:$D$53) -> 59058 | C8: =SUM('births-by-mothers-age'!$C$11:$C$18) -> 59193 | D8: =C8-B8 -> 135 | F8: =SUM('births-by-mothers-age'!$C$11:$C$12)/$C$8 * 100 -> 7.3893873 | G8: =F8/100 -> 0.073893873 | H8: =G8 * C8 -> 4374 | I8: =SUM('births-by-mothers-age'!$C$13:$C$16)/$C$8 *100 -> 88.961533 | J8: =I8/100 -> 0.88961533 | K8: =C8*J8 -> 52659 | L8: =SUM('births-by-mothers-age'!$C$17:$C$18)/$C$8 * 100 -> 3.6490801 | M8: =L8/100 -> 0.036490801 | N8: =C8*M8 -> 2160 | P8: =I8+L8 -> 92.610613 | T8: Mothers > 40 2022 (%) | U8: =L24 -> 4.0399409 | W8: Teen Mother in 2022 (%) | X8: =F24 -> 2.9191502 | AA8: =L9-L8 -> 0.065727574 | AC8: =F9-F8 -> 0.34472058
A9: 2007 | B9: =SUM('births-deaths-by-region'!$D$74:$D$89) -> 63873 | C9: =SUM('births-by-mothers-age'!$C$20:$C$27) -> 64041 | D9: =C9-B9 -> 168 | F9: =SUM('births-by-mothers-age'!$C$20:$C$21)/$C$9 * 100 -> 7.7341078 | G9: =F9/100 -> 0.077341078 | H9: =G9 * C9 -> 4953 | I9: =SUM('births-by-mothers-age'!$C$22:$C$25)/$C$9 * 100 -> 88.551084 | J9: =I9/100 -> 0.88551084 | K9: =C9*J9 -> 56709 | L9: =SUM('births-by-mothers-age'!$C$26:$C$27)/ $C$9 * 100 -> 3.7148077 | M9: =L9/100 -> 0.037148077 | N9: =C9*M9 -> 2379 | P9: =I9+L9 -> 92.265892 | T9: Absolute Change (% point) | U9: =U8-U7 -> 0.41321327 | W9: Absolute Decline (% point) | X9: =X7-X8 -> 4.2407791 | AA9: =L10-L9 -> -0.012658217 | AC9: =F10-F9 -> 0.38357762
A10: 2008 | B10: =SUM('births-deaths-by-region'!$D$110:$D$125) -> 64278 | C10: =SUM('births-by-mothers-age'!$C$29:$C$36) -> 64341 | D10: =C10-B10 -> 63 | F10: =SUM('births-by-mothers-age'!$C$29:$C$30)/$C$10 * 100 -> 8.1176855 | G10: =F10/100 -> 0.081176855 | H10: =G10 * C10 -> 5223 | I10: =SUM('births-by-mothers-age'!$C$31:$C$34)/$C$10 * 100 -> 88.180165 | J10: =I10/100 -> 0.88180165 | K10: =C10*J10 -> 56736 | L10: =SUM('births-by-mothers-age'!$C$35:$C$36)/$C$10 * 100 -> 3.7021495 | M10: =L10/100 -> 0.037021495 | N10: =C10*M10 -> 2382 | P10: =I10+L10 -> 91.882315 | T10: Relative change (%) | U10: =(U8-U7)/U7 * 100 -> 11.393557 | W10: Relative Decline(%) | X10: =(X9)/X7*100 -> 59.229343 | AA10: =L11-L10 -> 0.22647334 | AC10: =F11-F10 -> -0.64898492
A11: 2009 | B11: =SUM('births-deaths-by-region'!$D$146:$D$161) -> 62457 | C11: =SUM('births-by-mothers-age'!$C$38:$C$45) -> 62541 | D11: =C11-B11 -> 84 | F11: =SUM('births-by-mothers-age'!$C$38:$C$39)/$C$11 * 100 -> 7.4687005 | G11: =F11/100 -> 0.074687005 | H11: =G11 * C11 -> 4671 | I11: =SUM('births-by-mothers-age'!$C$40:$C$43)/$C$11 * 100 -> 88.602677 | J11: =I11/100 -> 0.88602677 | K11: =C11*J11 -> 55413 | L11: =SUM('births-by-mothers-age'!$C$44:$C$45)/$C$11 * 100 -> 3.9286228 | M11: =L11/100 -> 0.039286228 | N11: =C11*M11 -> 2457 | P11: =I11+L11 -> 92.531299 | T11: Average annual change(% point) | U11: =(U9)/(A24-A7) -> 0.024306663 | W11: Average Annual Decline (% point) | X11: =(X9)/(A24-A7) -> 0.24945759 | AA11: =L12-L11 -> 0.17504888 | AC11: =F12-F11 -> -0.345966
A12: 2010 | B12: =SUM('births-deaths-by-region'!$D$182:$D$197) -> 63813 | C12: =SUM('births-by-mothers-age'!$C$47:$C$54) -> 63894 | D12: =C12-B12 -> 81 | F12: =SUM('births-by-mothers-age'!$C$47:$C$48)/$C$12 * 100 -> 7.1227345 | G12: =F12/100 -> 0.071227345 | H12: =G12 * C12 -> 4551 | I12: =SUM('births-by-mothers-age'!$C$49:$C$52)/ $C$12 * 100 -> 88.773594 | J12: =I12/100 -> 0.88773594 | K12: =C12*J12 -> 56721 | L12: =SUM('births-by-mothers-age'!$C$53:$C$54)/$C$12 *100 -> 4.1036717 | M12: =L12/100 -> 0.041036717 | N12: =C12*M12 -> 2622 | P12: =I12+L12 -> 92.877265 | T12: Actual Birth to Mother > 40 in 2005 | U12: =B7*(L7/100) -> 2091.7152 | W12: Actual Teen Birth in 2005 | X12: =B7*(F7/100) -> 4129.4892 | AA12: =L13-L12 -> 0.039380864 | AC12: =F13-F12 -> -0.59547246
A13: 2011 | B13: =SUM('births-deaths-by-region'!$D$218:$D$233) -> 61380 | C13: =SUM('births-by-mothers-age'!$C$56:$C$63) -> 61404 | D13: =C13-B13 -> 24 | F13: =SUM('births-by-mothers-age'!$C$56:$C$57)/$C$13 * 100 -> 6.5272621 | G13: =F13/100 -> 0.065272621 | H13: =G13 * C13 -> 4008 | I13: =SUM('births-by-mothers-age'!$C$58:$C$61)/$C$13 * 100 -> 89.329685 | J13: =I13/100 -> 0.89329685 | K13: =C13*J13 -> 54852 | L13: =SUM('births-by-mothers-age'!$C$62:$C$63)/$C$13 * 100 -> 4.1430526 | M13: =L13/100 -> 0.041430526 | N13: =C13*M13 -> 2544 | P13: =I13+L13 -> 93.472738 | T13: Actual Birth to Mother > 40 in 2022 | U13: =B24*(L24/100) -> 2378.7576 | W13: Actual Teen Birth in 2005 | X13: =B24*(F24/100) -> 1718.8249 | AA13: =L14-L13 -> 0.16234634 | AC13: =F14-F13 -> -0.33886409
A14: 2012 | B14: =SUM('births-deaths-by-region'!$D$254:$D$269) -> 61164 | C14: =SUM('births-by-mothers-age'!$C$65:$C$72) -> 61179 | D14: =C14-B14 -> 15 | F14: =SUM('births-by-mothers-age'!$C$65:$C$66)/$C$14 * 100 -> 6.188398 | G14: =F14/100 -> 0.06188398 | H14: =G14 * C14 -> 3786 | I14: =SUM('births-by-mothers-age'!$C$67:$C$70)/$C$14 * 100 -> 89.506203 | J14: =I14/100 -> 0.89506203 | K14: =C14*J14 -> 54759 | L14: =SUM('births-by-mothers-age'!$C$71:$C$72)/$C$14 * 100 -> 4.3053989 | M14: =L14/100 -> 0.043053989 | N14: =C14*M14 -> 2634 | P14: =I14+L14 -> 93.811602 | W14: Reduction in Teen Birth | X14: =X12-X13 -> 2410.6644 | AA14: =L15-L14 -> 0.093068522 | AC14: =F15-F14 -> -0.56387691
A15: 2013 | B15: =SUM('births-deaths-by-region'!$D$290:$D$305) -> 58701 | C15: =SUM('births-by-mothers-age'!$C$74:$C$81) -> 58725 | D15: =C15-B15 -> 24 | F15: =SUM('births-by-mothers-age'!$C$74:$C$75)/$C$15 * 100 -> 5.6245211 | G15: =F15/100 -> 0.056245211 | H15: =G15 * C15 -> 3303 | I15: =SUM('births-by-mothers-age'!$C$76:$C$79)/$C$15 * 100 -> 89.977011 | J15: =I15/100 -> 0.89977011 | K15: =C15*J15 -> 52839 | L15: =SUM('births-by-mothers-age'!$C$80:$C$81)/$C$15 * 100 -> 4.3984674 | M15: =L15/100 -> 0.043984674 | N15: =C15*M15 -> 2583 | P15: =I15+L15 -> 94.375479 | T15: Year with largest increase in mothers > 40 | U15: =INDEX(A7:A24,MATCH(MAX(L7:L24),L7:L24,0)) -> 2013 | W15: % Reduction actual Teen Birth | X15: =(X14)/X12*100 -> 58.376817 | AA15: =L16-L15 -> -0.10077351 | AC15: =F16-F15 -> -0.51969927
A16: 2014 | B16: =SUM('births-deaths-by-region'!$D$326:$D$341) -> 57219 | C16: =SUM('births-by-mothers-age'!$C$83:$C$90) -> 57240 | D16: =C16-B16 -> 21 | F16: =SUM('births-by-mothers-age'!$C$83:$C$84)/ $C$16 * 100 -> 5.1048218 | G16: =F16/100 -> 0.051048218 | H16: =G16 * C16 -> 2922 | I16: =SUM('births-by-mothers-age'!$C$85:$C$88)/$C$16 * 100 -> 90.597484 | J16: =I16/100 -> 0.90597484 | K16: =C16*J16 -> 51858 | L16: =SUM('births-by-mothers-age'!$C$89:$C$90)/$C$16 * 100 -> 4.2976939 | M16: =L16/100 -> 0.042976939 | N16: =C16*M16 -> 2460 | P16: =I16+L16 -> 94.895178 | T16: Year with lowest number of mothers > 40 | U16: =INDEX(A7:A24,MATCH(MIN(L7:L24),L7:L24,0)) -> 2005 | AA16: =L17-L16 -> -0.13491808 | AC16: =F17-F16 -> -0.41125518
A17: 2015 | B17: =SUM('births-deaths-by-region'!$D$362:$D$377) -> 61029 | C17: =SUM('births-by-mothers-age'!$C$92:$C$99) -> 61041 | D17: =C17-B17 -> 12 | F17: =SUM('births-by-mothers-age'!$C$92:$C$93)/$C$17 * 100 -> 4.6935666 | G17: =F17/100 -> 0.046935666 | H17: =G17 * C17 -> 2865 | I17: =SUM('births-by-mothers-age'!$C$94:$C$97)/ $C$17 * 100 -> 91.143658 | J17: =I17/100 -> 0.91143658 | K17: =C17*J17 -> 55635 | L17: =SUM('births-by-mothers-age'!$C$98:$C$99)/$C$17 * 100 -> 4.1627758 | M17: =L17/100 -> 0.041627758 | N17: =C17*M17 -> 2541 | P17: =I17+L17 -> 95.306433 | W17: Year with the largest decrease in teen mothers | X17: =INDEX(A7:A24,MATCH(MIN(F7:F24),F7:F24,0)) -> 2021 | AA17: =L18-L17 -> -0.10926751 | AC17: =F18-F17 -> -0.51890736
A18: 2016 | B18: =SUM('births-deaths-by-region'!$D$398:$D$413) -> 59406 | C18: =SUM('births-by-mothers-age'!$C$101:$C$108) -> 59430 | D18: =C18-B18 -> 24 | F18: =SUM('births-by-mothers-age'!$C$101:$C$102)/$C$18 * 100 -> 4.1746593 | G18: =F18/100 -> 0.041746593 | H18: =G18 * C18 -> 2481 | I18: =SUM('births-by-mothers-age'!$C$103:$C$106)/$C$18 * 100 -> 91.771832 | J18: =I18/100 -> 0.91771832 | K18: =C18*J18 -> 54540 | L18: =SUM('births-by-mothers-age'!$C$107:$C$108)/$C$18 * 100 -> 4.0535083 | M18: =L18/100 -> 0.040535083 | N18: =C18*M18 -> 2409 | P18: =I18+L18 -> 95.825341 | W18: Year with the highest number of teen mothers | X18: =INDEX(A7:A24,MATCH(MAX(F7:F24),F7:F24,0)) -> 2008 | AA18: =L19-L18 -> 0.043119753 | AC18: =F19-F18 -> -0.28940511
A19: 2017 | B19: =SUM('births-deaths-by-region'!$D$434:$D$449) -> 59595 | C19: =SUM('births-by-mothers-age'!$C$110:$C$117) -> 59610 | D19: =C19-B19 -> 15 | F19: =SUM('births-by-mothers-age'!$C$110:$C$111)/$C$19 * 100 -> 3.8852542 | G19: =F19/100 -> 0.038852542 | H19: =G19 * C19 -> 2316 | I19: =SUM('births-by-mothers-age'!$C$112:$C$115) / $C$19 * 100 -> 92.018118 | J19: =I19/100 -> 0.92018118 | K19: =C19*J19 -> 54852 | L19: =SUM('births-by-mothers-age'!$C$116:$C$117)/$C$19 * 100 -> 4.0966281 | M19: =L19/100 -> 0.040966281 | N19: =C19*M19 -> 2442 | P19: =I19+L19 -> 96.114746 | U19: =INDEX(A7:A24,MATCH(MIN(F7:F24),F7:F24,0)) -> 2021 | AA19: =L20-L19 -> -0.13592488 | AC19: =F20-F19 -> -0.30717763
A20: 2018 | B20: =SUM('births-deaths-by-region'!$D$470:$D$485) -> 57996 | C20: =SUM('births-by-mothers-age'!$C$119:$C$126) -> 58020 | D20: =C20-B20 -> 24 | F20: =SUM('births-by-mothers-age'!$C$119:$C$120)/$C$20 * 100 -> 3.5780765 | G20: =F20/100 -> 0.035780765 | H20: =G20 * C20 -> 2076 | I20: =SUM('births-by-mothers-age'!$C$121:$C$124)/$C$20 * 100 -> 92.46122 | J20: =I20/100 -> 0.9246122 | K20: =C20*J20 -> 53646 | L20: =SUM('births-by-mothers-age'!$C$125:$C$126)/$C$20 * 100 -> 3.9607032 | M20: =L20/100 -> 0.039607032 | N20: =C20*M20 -> 2298 | P20: =I20+L20 -> 96.421923 | AA20: =L21-L20 -> 0.098448748 | AC20: =F21-F20 -> -0.23317436
A21: 2019 | B21: =SUM('births-deaths-by-region'!$D$506:$D$521) -> 59613 | C21: =SUM('births-by-mothers-age'!$C$128:$C$135) -> 59643 | D21: =C21-B21 -> 30 | F21: =SUM('births-by-mothers-age'!$C$128:$C$129)/$C$21 * 100 -> 3.3449022 | G21: =F21/100 -> 0.033449022 | H21: =G21 * C21 -> 1995 | I21: =SUM('births-by-mothers-age'!$C$130:$C$133)/$C$21 *100 -> 92.595946 | J21: =I21/100 -> 0.92595946 | K21: =C21*J21 -> 55227 | L21: =SUM('births-by-mothers-age'!$C$134:$C$135)/$C$21 * 100 -> 4.059152 | M21: =L21/100 -> 0.04059152 | N21: =C21*M21 -> 2421 | P21: =I21+L21 -> 96.655098 | AA21: =L22-L21 -> -0.15107004 | AC21: =F22-F21 -> -0.056902585
A22: 2020 | B22: =SUM('births-deaths-by-region'!$D$542:$D$557) -> 57546 | C22: =SUM('births-by-mothers-age'!$C$137:$C$144) -> 57573 | D22: =C22-B22 -> 27 | F22: =SUM('births-by-mothers-age'!$C$137:$C$138)/$C$22 * 100 -> 3.2879996 | G22: =F22/100 -> 0.032879996 | H22: =G22 * C22 -> 1893 | I22: =SUM('births-by-mothers-age'!$C$139:$C$142)/$C$22 * 100 -> 92.803919 | J22: =I22/100 -> 0.92803919 | K22: =C22*J22 -> 53430 | L22: =SUM('births-by-mothers-age'!$C$143:$C$144)/$C$22 * 100 -> 3.9080819 | M22: =L22/100 -> 0.039080819 | N22: =C22*M22 -> 2250 | P22: =I22+L22 -> 96.712 | AA22: =L23-L22 -> -0.098509404 | AC22: =F23-F22 -> -0.56760686
A23: 2021 | B23: =SUM('births-deaths-by-region'!$D$578:$D$593) -> 58647 | C23: =SUM('births-by-mothers-age'!$C$146:$C$153) -> 58668 | D23: =C23-B23 -> 21 | F23: =SUM('births-by-mothers-age'!$C$146:$C$147)/$C$23 * 100 -> 2.7203927 | G23: =F23/100 -> 0.027203927 | H23: =G23 * C23 -> 1596 | I23: =SUM('births-by-mothers-age'!$C$148:$C$151)/$C$23 * 100 -> 93.470035 | J23: =I23/100 -> 0.93470035 | K23: =C23*J23 -> 54837 | L23: =SUM('births-by-mothers-age'!$C$152:$C$153)/$C$23 * 100 -> 3.8095725 | M23: =L23/100 -> 0.038095725 | N23: =C23*M23 -> 2235 | P23: =I23+L23 -> 97.279607 | AA23: =L24-L23 -> 0.23036839 | AC23: =F24-F23 -> 0.19875752
A24: 2022 | B24: =SUM('births-deaths-by-region'!$D$614:$D$629) -> 58881 | C24: =SUM('births-by-mothers-age'!$C$155:$C$162) -> 58887 | D24: =C24-B24 -> 6 | F24: =SUM('births-by-mothers-age'!$C$155:$C$156)/$C$24 * 100 -> 2.9191502 | G24: =F24/100 -> 0.029191502 | H24: =G24 * C24 -> 1719 | I24: =SUM('births-by-mothers-age'!$C$157:$C$160)/$C$24 * 100 -> 93.040909 | J24: =I24/100 -> 0.93040909 | K24: =C24*J24 -> 54789 | L24: =SUM('births-by-mothers-age'!$C$161:$C$162)/$C$24 * 100 -> 4.0399409 | M24: =L24/100 -> 0.040399409 | N24: =C24*M24 -> 2379 | P24: =I24+L24 -> 97.08085 | AA24: =L25-L24 -> -4.0399409 | AC24: =F25-F24 -> -2.9191502

Sheet births-deaths-by-region
A1: Period | B1: Birth_Death | C1: Region | D1: Count
A2: 2005 | B2: Births | C2: Northland region | D2: 2067
A3: 2005 | B3: Births | C3: Auckland region | D3: 20745
A4: 2005 | B4: Births | C4: Waikato region | D4: 5667
A5: 2005 | B5: Births | C5: Bay of Plenty region | D5: 3771
A6: 2005 | B6: Births | C6: Gisborne region | D6: 777
A7: 2005 | B7: Births | C7: Hawke's Bay region | D7: 2115
A8: 2005 | B8: Births | C8: Taranaki region | D8: 1410
A9: 2005 | B9: Births | C9: Manawatu-Wanganui region | D9: 3093
A10: 2005 | B10: Births | C10: Wellington region | D10: 6225
A11: 2005 | B11: Births | C11: Tasman region | D11: 513
A12: 2005 | B12: Births | C12: Nelson region | D12: 519
A13: 2005 | B13: Births | C13: Marlborough region | D13: 471
... A649: 2022 | B649: Deaths | C649: New Zealand | D649: 38574

Sheet births-deaths-natural-increase
A1: Period | B1: Births_Deaths_or_Natural_Increase | C1: Count
A2: 2000 | B2: Births | C2: 56604
A3: 2001 | B3: Births | C3: 55800
A4: 2002 | B4: Births | C4: 54021
A5: 2003 | B5: Births | C5: 56136
A6: 2004 | B6: Births | C6: 58074
A7: 2005 | B7: Births | C7: 57744
A8: 2006 | B8: Births | C8: 59193
A9: 2007 | B9: Births | C9: 64044
A10: 2008 | B10: Births | C10: 64341
A11: 2009 | B11: Births | C11: 62541
A12: 2010 | B12: Births | C12: 63897
A13: 2011 | B13: Births | C13: 61404
... A70: 2022 | B70: Natural_Increase | C70: 20313

Sheet births-by-mothers-age
A1: Period | B1: Mothers_Age | C1: Count | D1: Age_specific_birth_rate | F1: Avg Age | G1: Median Age
A2: 2005 | B2: Under 15 | C2: 36 | D2: =_xlfn.XLOOKUP(D1,'age-specific-fertility-rates'!$A$1:$C$1,'age-specific-fertility-rates'!$A$2:$C$2) -> 0.2 | F2: 15 | G2: =MEDIAN(F2:F9) -> 29.5
A3: 2005 | B3: 15–19 | C3: 4098 | D3: =_xlfn.XLOOKUP(D1,'age-specific-fertility-rates'!$A$1:$C$1,'age-specific-fertility-rates'!$A$3:$C$3) -> 27.2 | F3: =(15+19)/2 -> 17
A4: 2005 | B4: 20–24 | C4: 9708 | D4: =_xlfn.XLOOKUP(D1,'age-specific-fertility-rates'!$A$1:$C$1,'age-specific-fertility-rates'!$A$4:$C$4) -> 67.6 | F4: =(20+24)/2 -> 22
A5: 2005 | B5: 25–29 | C5: 13797 | D5: =_xlfn.XLOOKUP(D1,'age-specific-fertility-rates'!$A$1:$C$1,'age-specific-fertility-rates'!$A$5:$C$5) -> 104.9 | F5: =(25+29)/2 -> 27
A6: 2005 | B6: 30–34 | C6: 17976 | D6: =_xlfn.XLOOKUP($D$1,'age-specific-fertility-rates'!$A$1:$C$1,'age-specific-fertility-rates'!$A$6:$C$6) -> 117.1 | F6: =(30+34)/2 -> 32
A7: 2005 | B7: 35–39 | C7: 10029 | D7: =_xlfn.XLOOKUP(D1,'age-specific-fertility-rates'!$A$1:$C$1,'age-specific-fertility-rates'!$A$7:$C$7) -> 62.3 | F7: =(35+39)/2 -> 37
A8: 2005 | B8: 40–44 | C8: 2001 | D8: =_xlfn.XLOOKUP($D$1,'age-specific-fertility-rates'!$A$1:$C$1,'age-specific-fertility-rates'!$A$8:$C$8) -> 12 | F8: =(40+44)/2 -> 42
A9: 2005 | B9: 45 and over | C9: 93 | D9: =_xlfn.XLOOKUP($D$1,'age-specific-fertility-rates'!$A$1:$C$1,'age-specific-fertility-rates'!$A$9:$C$9) -> 0.6 | F9: 45
A10: 2005 | B10: Total | C10: 57747
A11: 2006 | B11: Under 15 | C11: 36 | D11: =_xlfn.XLOOKUP($D$1,'age-specific-fertility-rates'!$A$1:$C$1,'age-specific-fertility-rates'!$A$10:$C$10) -> 0.2
A12: 2006 | B12: 15–19 | C12: 4338 | D12: =_xlfn.XLOOKUP($D$1,'age-specific-fertility-rates'!$A$1:$C$1,'age-specific-fertility-rates'!$A$11:$C$11) -> 28.1
A13: 2006 | B13: 20–24 | C13: 10308 | D13: =_xlfn.XLOOKUP($D$1,'age-specific-fertility-rates'!$A$1:$C$1,'age-specific-fertility-rates'!$A$12:$C$12) -> 70.9
A14: 2006 | B14: 25–29 | C14: 14082 | D14: =_xlfn.XLOOKUP($D$1,'age-specific-fertility-rates'!$A$1:$C$1,'age-specific-fertility-rates'!$A$13:$C$13) -> 105.2
A15: 2006 | B15: 30–34 | C15: 17868 | D15: =_xlfn.XLOOKUP($D$1,'age-specific-fertility-rates'!$A$1:$C$1,'age-specific-fertility-rates'!$A$14:$C$14) -> 119.3
A16: 2006 | B16: 35–39 | C16: 10401 | D16: =_xlfn.XLOOKUP($D$1,'age-specific-fertility-rates'!$A$1:$C$1,'age-specific-fertility-rates'!$A$15:$C$15) -> 63.7
A17: 2006 | B17: 40–44 | C17: 2052 | D17: =_xlfn.XLOOKUP($D$1,'age-specific-fertility-rates'!$A$1:$C$1,'age-specific-fertility-rates'!$A$16:$C$16) -> 12.3
A18: 2006 | B18: 45 and over | C18: 108 | D18: =_xlfn.XLOOKUP($D$1,'age-specific-fertility-rates'!$A$1:$C$1,'age-specific-fertility-rates'!$A$17:$C$17) -> 0.7
A19: 2006 | B19: Total | C19: 59193
A20: 2007 | B20: Under 15 | C20: 51 | D20: =_xlfn.XLOOKUP($D$1,'age-specific-fertility-rates'!$A$1:$C$1,'age-specific-fertility-rates'!$A$18:$C$18) -> 0.3
A21: 2007 | B21: 15–19 | C21: 4902 | D21: =_xlfn.XLOOKUP($D$1,'age-specific-fertility-rates'!$A$1:$C$1,'age-specific-fertility-rates'!$A$19:$C$19) -> 31.4
A22: 2007 | B22: 20–24 | C22: 11094 | D22: =_xlfn.XLOOKUP($D$1,'age-specific-fertility-rates'!$A$1:$C$1,'age-specific-fertility-rates'!$A$20:$C$20) -> 76.5
A23: 2007 | B23: 25–29 | C23: 15516 | D23: =_xlfn.XLOOKUP($D$1,'age-specific-fertility-rates'!$A$1:$C$1,'age-specific-fertility-rates'!$A$21:$C$21) -> 114.2
A24: 2007 | B24: 30–34 | C24: 18498 | D24: =_xlfn.XLOOKUP($D$1,'age-specific-fertility-rates'!$A$1:$C$1,'age-specific-fertility-rates'!$A$22:$C$22) -> 126.9
A25: 2007 | B25: 35–39 | C25: 11601 | D25: =_xlfn.XLOOKUP($D$1,'age-specific-fertility-rates'!$A$1:$C$1,'age-specific-fertility-rates'!$A$23:$C$23) -> 70.3
A26: 2007 | B26: 40–44 | C26: 2268 | D26: =_xlfn.XLOOKUP($D$1,'age-specific-fertility-rates'!$A$1:$C$1,'age-specific-fertility-rates'!$A$24:$C$24) -> 13.7
A27: 2007 | B27: 45 and over | C27: 111 | D27: =_xlfn.XLOOKUP($D$1,'age-specific-fertility-rates'!$A$1:$C$1,'age-specific-fertility-rates'!$A$25:$C$25) -> 0.7
A28: 2007 | B28: Total | C28: 64044
A29: 2008 | B29: Under 15 | C29: 39 | D29: =_xlfn.XLOOKUP($D$1,'age-specific-fertility-rates'!$A$1:$C$1,'age-specific-fertility-rates'!$A$26:$C$26) -> 0.3
A30: 2008 | B30: 15–19 | C30: 5184 | D30: =_xlfn.XLOOKUP($D$1,'age-specific-fertility-rates'!$A$1:$C$1,'age-specific-fertility-rates'!$A$27:$C$27) -> 33.1
A31: 2008 | B31: 20–24 | C31: 11493 | D31: =_xlfn.XLOOKUP($D$1,'age-specific-fertility-rates'!$A$1:$C$1,'age-specific-fertility-rates'!$A$28:$C$28) -> 79.5
A32: 2008 | B32: 25–29 | C32: 15612 | D32: =_xlfn.XLOOKUP($D$1,'age-specific-fertility-rates'!$A$1:$C$1,'age-specific-fertility-rates'!$A$29:$C$29) -> 113.4
A33: 2008 | B33: 30–34 | C33: 17823 | D33: =_xlfn.XLOOKUP($D$1,'age-specific-fertility-rates'!$A$1:$C$1,'age-specific-fertility-rates'!$A$30:$C$30) -> 125.3
A34: 2008 | B34: 35–39 | C34: 11808 | D34: =_xlfn.XLOOKUP($D$1,'age-specific-fertility-rates'!$A$1:$C$1,'age-specific-fertility-rates'!$A$31:$C$31) -> 71.6
A35: 2008 | B35: 40–44 | C35: 2262 | D35: =_xlfn.XLOOKUP($D$1,'age-specific-fertility-rates'!$A$1:$C$1,'age-specific-fertility-rates'!$A$32:$C$32) -> 13.9
A36: 2008 | B36: 45 and over | C36: 120 | D36: =_xlfn.XLOOKUP($D$1,'age-specific-fertility-rates'!$A$1:$C$1,'age-specific-fertility-rates'!$A$33:$C$33) -> 0.7
A37: 2008 | B37: Total | C37: 64341
A38: 2009 | B38: Under 15 | C38: 30 | D38: =_xlfn.XLOOKUP($D$1,'age-specific-fertility-rates'!$A$1:$C$1,'age-specific-fertility-rates'!$A$34:$C$34) -> 0.2
A39: 2009 | B39: 15–19 | C39: 4641 | D39: =_xlfn.XLOOKUP($D$1,'age-specific-fertility-rates'!$A$1:$C$1,'age-specific-fertility-rates'!$A$35:$C$35) -> 29.6
A40: 2009 | B40: 20–24 | C40: 11502 | D40: =_xlfn.XLOOKUP($D$1,'age-specific-fertility-rates'!$A$1:$C$1,'age-specific-fertility-rates'!$A$36:$C$36) -> 78.7
...

Sheet age-specific-fertility-rates
A1: Period | B1: Mothers_Age | C1: Age_specific_birth_rate
A2: 2005 | B2: Under 15 | C2: 0.2
A3: 2005 | B3: 15–19 | C3: 27.2
A4: 2005 | B4: 20–24 | C4: 67.6
A5: 2005 | B5: 25–29 | C5: 104.9
A6: 2005 | B6: 30–34 | C6: 117.1
A7: 2005 | B7: 35–39 | C7: 62.3
A8: 2005 | B8: 40–44 | C8: 12
A9: 2005 | B9: 45 and over | C9: 0.6
A10: 2006 | B10: Under 15 | C10: 0.2
A11: 2006 | B11: 15–19 | C11: 28.1
A12: 2006 | B12: 20–24 | C12: 70.9
A13: 2006 | B13: 25–29 | C13: 105.2
... A145: 2022 | B145: 45 and over | C145: 0.8
